<mujoco model="g1">
  <compiler angle="radian" meshdir="meshes"/>

  <asset>
    <mesh name="pelvis" file="pelvis.STL"/>
    <mesh name="pelvis_contour_link" file="pelvis_contour_link.STL"/>
    <mesh name="left_hip_pitch_link" file="left_hip_pitch_link.STL"/>
    <mesh name="left_hip_roll_link" file="left_hip_roll_link.STL"/>
    <mesh name="left_hip_yaw_link" file="left_hip_yaw_link.STL"/>
    <mesh name="left_knee_link" file="left_knee_link.STL"/>
    <mesh name="left_ankle_pitch_link" file="left_ankle_pitch_link.STL"/>
    <mesh name="left_ankle_roll_link" file="left_ankle_roll_link.STL"/>
    <mesh name="right_hip_pitch_link" file="right_hip_pitch_link.STL"/>
    <mesh name="right_hip_roll_link" file="right_hip_roll_link.STL"/>
    <mesh name="right_hip_yaw_link" file="right_hip_yaw_link.STL"/>
    <mesh name="right_knee_link" file="right_knee_link.STL"/>
    <mesh name="right_ankle_pitch_link" file="right_ankle_pitch_link.STL"/>
    <mesh name="right_ankle_roll_link" file="right_ankle_roll_link.STL"/>
    <mesh name="waist_yaw_link" file="waist_yaw_link_rev_1_0.STL"/>
    <mesh name="waist_roll_link" file="waist_roll_link_rev_1_0.STL"/>
    <mesh name="torso_link" file="torso_link_rev_1_0.STL"/>
    <mesh name="logo_link" file="logo_link.STL"/>
    <mesh name="head_link" file="head_link.STL"/>
    <mesh name="left_shoulder_pitch_link" file="left_shoulder_pitch_link.STL"/>
    <mesh name="left_shoulder_roll_link" file="left_shoulder_roll_link.STL"/>
    <mesh name="left_shoulder_yaw_link" file="left_shoulder_yaw_link.STL"/>
    <mesh name="left_elbow_link" file="left_elbow_link.STL"/>
    <mesh name="left_wrist_roll_link" file="left_wrist_roll_link.STL"/>
    <mesh name="left_wrist_pitch_link" file="left_wrist_pitch_link.STL"/>
    <mesh name="left_wrist_yaw_link" file="left_wrist_yaw_link.STL"/>
    <mesh name="left_hand_palm_link" file="left_hand_palm_link.STL"/>
    <mesh name="left_hand_thumb_0_link" file="left_hand_thumb_0_link.STL"/>
    <mesh name="left_hand_thumb_1_link" file="left_hand_thumb_1_link.STL"/>
    <mesh name="left_hand_thumb_2_link" file="left_hand_thumb_2_link.STL"/>
    <mesh name="left_hand_middle_0_link" file="left_hand_middle_0_link.STL"/>
    <mesh name="left_hand_middle_1_link" file="left_hand_middle_1_link.STL"/>
    <mesh name="left_hand_index_0_link" file="left_hand_index_0_link.STL"/>
    <mesh name="left_hand_index_1_link" file="left_hand_index_1_link.STL"/>
    <mesh name="right_shoulder_pitch_link" file="right_shoulder_pitch_link.STL"/>
    <mesh name="right_shoulder_roll_link" file="right_shoulder_roll_link.STL"/>
    <mesh name="right_shoulder_yaw_link" file="right_shoulder_yaw_link.STL"/>
    <mesh name="right_elbow_link" file="right_elbow_link.STL"/>
    <mesh name="right_wrist_roll_link" file="right_wrist_roll_link.STL"/>
    <mesh name="right_wrist_pitch_link" file="right_wrist_pitch_link.STL"/>
    <mesh name="right_wrist_yaw_link" file="right_wrist_yaw_link.STL"/>
    <mesh name="right_hand_palm_link" file="right_hand_palm_link.STL"/>
    <mesh name="right_hand_thumb_0_link" file="right_hand_thumb_0_link.STL"/>
    <mesh name="right_hand_thumb_1_link" file="right_hand_thumb_1_link.STL"/>
    <mesh name="right_hand_thumb_2_link" file="right_hand_thumb_2_link.STL"/>
    <mesh name="right_hand_middle_0_link" file="right_hand_middle_0_link.STL"/>
    <mesh name="right_hand_middle_1_link" file="right_hand_middle_1_link.STL"/>
    <mesh name="right_hand_index_0_link" file="right_hand_index_0_link.STL"/>
    <mesh name="right_hand_index_1_link" file="right_hand_index_1_link.STL"/>
    <!-- Inspire Hand meshes (both sides) -->
    <mesh name="L_hand_base_link"  file="L_hand_base_link.STL"/>
    <mesh name="inspire_L_Link11"  file="Link11_L.STL"/>
    <mesh name="inspire_L_Link12"  file="Link12_L.STL"/>
    <mesh name="inspire_L_Link13"  file="Link13_L.STL"/>
    <mesh name="inspire_L_Link14"  file="Link14_L.STL"/>
    <mesh name="inspire_L_Link15"  file="Link15_L.STL"/>
    <mesh name="inspire_L_Link16"  file="Link16_L.STL"/>
    <mesh name="inspire_L_Link17"  file="Link17_L.STL"/>
    <mesh name="inspire_L_Link18"  file="Link18_L.STL"/>
    <mesh name="inspire_L_Link19"  file="Link19_L.STL"/>
    <mesh name="inspire_L_Link20"  file="Link20_L.STL"/>
    <mesh name="inspire_L_Link21"  file="Link21_L.STL"/>
    <mesh name="inspire_L_Link22"  file="Link22_L.STL"/>
    <mesh name="R_hand_base_link"  file="R_hand_base_link.STL"/>
    <mesh name="inspire_R_Link11"  file="Link11_R.STL"/>
    <mesh name="inspire_R_Link12"  file="Link12_R.STL"/>
    <mesh name="inspire_R_Link13"  file="Link13_R.STL"/>
    <mesh name="inspire_R_Link14"  file="Link14_R.STL"/>
    <mesh name="inspire_R_Link15"  file="Link15_R.STL"/>
    <mesh name="inspire_R_Link16"  file="Link16_R.STL"/>
    <mesh name="inspire_R_Link17"  file="Link17_R.STL"/>
    <mesh name="inspire_R_Link18"  file="Link18_R.STL"/>
    <mesh name="inspire_R_Link19"  file="Link19_R.STL"/>
    <mesh name="inspire_R_Link20"  file="Link20_R.STL"/>
    <mesh name="inspire_R_Link21"  file="Link21_R.STL"/>
    <mesh name="inspire_R_Link22"  file="Link22_R.STL"/>
  </asset>

  <worldbody>
    <body name="pelvis" pos="0 0 0.793">
      <inertial pos="0 0 -0.07605" quat="1 0 -0.000399148 0" mass="3.813" diaginertia="0.010549 0.0093089 0.0079184"/>
      <joint name="floating_base_joint" type="free" limited="false" actuatorfrclimited="false"/>
      <geom type="mesh" contype="0" conaffinity="0" group="1" density="0" rgba="0.2 0.2 0.2 1" mesh="pelvis"/>
      <geom type="mesh" contype="0" conaffinity="0" group="1" density="0" rgba="0.7 0.7 0.7 1" mesh="pelvis_contour_link"/>
      <geom type="mesh" rgba="0.7 0.7 0.7 1" mesh="pelvis_contour_link"/>
      <site name="imu_in_pelvis" size="0.01" pos="0.04525 0 -0.08339"/>
      <body name="left_hip_pitch_link" pos="0 0.064452 -0.1027">
        <inertial pos="0.002741 0.047791 -0.02606" quat="0.954862 0.293964 0.0302556 0.030122" mass="1.35" diaginertia="0.00181517 0.00153422 0.00116212"/>
        <joint name="left_hip_pitch_joint" pos="0 0 0" axis="0 1 0" range="-2.5307 2.8798" actuatorfrcrange="-88 88"/>
        <geom type="mesh" contype="0" conaffinity="0" group="1" density="0" rgba="0.2 0.2 0.2 1" mesh="left_hip_pitch_link"/>
        <geom type="mesh" rgba="0.2 0.2 0.2 1" mesh="left_hip_pitch_link"/>
        <body name="left_hip_roll_link" pos="0 0.052 -0.030465" quat="0.996179 0 -0.0873386 0">
          <inertial pos="0.029812 -0.001045 -0.087934" quat="0.977808 -1.97119e-05 0.205576 -0.0403793" mass="1.52" diaginertia="0.00254986 0.00241169 0.00148755"/>
          <joint name="left_hip_roll_joint" pos="0 0 0" axis="1 0 0" range="-0.5236 2.9671" actuatorfrcrange="-139 139"/>
          <geom type="mesh" contype="0" conaffinity="0" group="1" density="0" rgba="0.7 0.7 0.7 1" mesh="left_hip_roll_link"/>
          <geom type="mesh" rgba="0.7 0.7 0.7 1" mesh="left_hip_roll_link"/>
          <body name="left_hip_yaw_link" pos="0.025001 0 -0.12412">
            <inertial pos="-0.057709 -0.010981 -0.15078" quat="0.600598 0.15832 0.223482 0.751181" mass="1.702" diaginertia="0.00776166 0.00717575 0.00160139"/>
            <joint name="left_hip_yaw_joint" pos="0 0 0" axis="0 0 1" range="-2.7576 2.7576" actuatorfrcrange="-88 88"/>
            <geom type="mesh" contype="0" conaffinity="0" group="1" density="0" rgba="0.7 0.7 0.7 1" mesh="left_hip_yaw_link"/>
            <geom type="mesh" rgba="0.7 0.7 0.7 1" mesh="left_hip_yaw_link"/>
            <body name="left_knee_link" pos="-0.078273 0.0021489 -0.17734" quat="0.996179 0 0.0873386 0">
              <inertial pos="0.005457 0.003964 -0.12074" quat="0.923418 -0.0327699 0.0158246 0.382067" mass="1.932" diaginertia="0.0113804 0.0112778 0.00146458"/>
              <joint name="left_knee_joint" pos="0 0 0" axis="0 1 0" range="-0.087267 2.8798" actuatorfrcrange="-139 139"/>
              <geom type="mesh" contype="0" conaffinity="0" group="1" density="0" rgba="0.7 0.7 0.7 1" mesh="left_knee_link"/>
              <geom type="mesh" rgba="0.7 0.7 0.7 1" mesh="left_knee_link"/>
              <body name="left_ankle_pitch_link" pos="0 -9.4445e-05 -0.30001">
                <inertial pos="-0.007269 0 0.011137" quat="0.603053 0.369225 0.369225 0.603053" mass="0.074" diaginertia="1.89e-05 1.40805e-05 6.9195e-06"/>
                <joint name="left_ankle_pitch_joint" pos="0 0 0" axis="0 1 0" range="-0.87267 0.5236" actuatorfrcrange="-50 50"/>
                <geom type="mesh" contype="0" conaffinity="0" group="1" density="0" rgba="0.7 0.7 0.7 1" mesh="left_ankle_pitch_link"/>
                <geom type="mesh" rgba="0.7 0.7 0.7 1" mesh="left_ankle_pitch_link"/>
                <body name="left_ankle_roll_link" pos="0 0 -0.017558">
                  <site name="left_foot" rgba="1 0 0 1" pos="0.04 0 -0.037"/>
                  <inertial pos="0.026505 0 -0.016425" quat="-0.000481092 0.728482 -0.000618967 0.685065" mass="0.608" diaginertia="0.00167218 0.0016161 0.000217621"/>
                  <joint name="left_ankle_roll_joint" pos="0 0 0" axis="1 0 0" range="-0.2618 0.2618" actuatorfrcrange="-50 50"/>
                  <geom type="mesh" contype="0" conaffinity="0" group="1" density="0" rgba="0.2 0.2 0.2 1" mesh="left_ankle_roll_link"/>
                  <geom size="0.005" pos="-0.05 0.025 -0.03" rgba="0.2 0.2 0.2 1"/>
                  <geom size="0.005" pos="-0.05 -0.025 -0.03" rgba="0.2 0.2 0.2 1"/>
                  <geom size="0.005" pos="0.12 0.03 -0.03" rgba="0.2 0.2 0.2 1"/>
                  <geom size="0.005" pos="0.12 -0.03 -0.03" rgba="0.2 0.2 0.2 1"/>
                </body>
              </body>
            </body>
          </body>
        </body>
      </body>
      <body name="right_hip_pitch_link" pos="0 -0.064452 -0.1027">
        <inertial pos="0.002741 -0.047791 -0.02606" quat="0.954862 -0.293964 0.0302556 -0.030122" mass="1.35" diaginertia="0.00181517 0.00153422 0.00116212"/>
        <joint name="right_hip_pitch_joint" pos="0 0 0" axis="0 1 0" range="-2.5307 2.8798" actuatorfrcrange="-88 88"/>
        <geom type="mesh" contype="0" conaffinity="0" group="1" density="0" rgba="0.2 0.2 0.2 1" mesh="right_hip_pitch_link"/>
        <geom type="mesh" rgba="0.2 0.2 0.2 1" mesh="right_hip_pitch_link"/>
        <body name="right_hip_roll_link" pos="0 -0.052 -0.030465" quat="0.996179 0 -0.0873386 0">
          <inertial pos="0.029812 0.001045 -0.087934" quat="0.977808 1.97119e-05 0.205576 0.0403793" mass="1.52" diaginertia="0.00254986 0.00241169 0.00148755"/>
          <joint name="right_hip_roll_joint" pos="0 0 0" axis="1 0 0" range="-2.9671 0.5236" actuatorfrcrange="-139 139"/>
          <geom type="mesh" contype="0" conaffinity="0" group="1" density="0" rgba="0.7 0.7 0.7 1" mesh="right_hip_roll_link"/>
          <geom type="mesh" rgba="0.7 0.7 0.7 1" mesh="right_hip_roll_link"/>
          <body name="right_hip_yaw_link" pos="0.025001 0 -0.12412">
            <inertial pos="-0.057709 0.010981 -0.15078" quat="0.751181 0.223482 0.15832 0.600598" mass="1.702" diaginertia="0.00776166 0.00717575 0.00160139"/>
            <joint name="right_hip_yaw_joint" pos="0 0 0" axis="0 0 1" range="-2.7576 2.7576" actuatorfrcrange="-88 88"/>
            <geom type="mesh" contype="0" conaffinity="0" group="1" density="0" rgba="0.7 0.7 0.7 1" mesh="right_hip_yaw_link"/>
            <geom type="mesh" rgba="0.7 0.7 0.7 1" mesh="right_hip_yaw_link"/>
            <body name="right_knee_link" pos="-0.078273 -0.0021489 -0.17734" quat="0.996179 0 0.0873386 0">
              <inertial pos="0.005457 -0.003964 -0.12074" quat="0.923439 0.0345276 0.0116333 -0.382012" mass="1.932" diaginertia="0.011374 0.0112843 0.00146452"/>
              <joint name="right_knee_joint" pos="0 0 0" axis="0 1 0" range="-0.087267 2.8798" actuatorfrcrange="-139 139"/>
              <geom type="mesh" contype="0" conaffinity="0" group="1" density="0" rgba="0.7 0.7 0.7 1" mesh="right_knee_link"/>
              <geom type="mesh" rgba="0.7 0.7 0.7 1" mesh="right_knee_link"/>
              <body name="right_ankle_pitch_link" pos="0 9.4445e-05 -0.30001">
                <inertial pos="-0.007269 0 0.011137" quat="0.603053 0.369225 0.369225 0.603053" mass="0.074" diaginertia="1.89e-05 1.40805e-05 6.9195e-06"/>
                <joint name="right_ankle_pitch_joint" pos="0 0 0" axis="0 1 0" range="-0.87267 0.5236" actuatorfrcrange="-50 50"/>
                <geom type="mesh" contype="0" conaffinity="0" group="1" density="0" rgba="0.7 0.7 0.7 1" mesh="right_ankle_pitch_link"/>
                <geom type="mesh" rgba="0.7 0.7 0.7 1" mesh="right_ankle_pitch_link"/>
                <body name="right_ankle_roll_link" pos="0 0 -0.017558">
                  <site name="right_foot" rgba="1 0 0 1" pos="0.04 0 -0.037"/>
                  <inertial pos="0.026505 0 -0.016425" quat="0.000481092 0.728482 0.000618967 0.685065" mass="0.608" diaginertia="0.00167218 0.0016161 0.000217621"/>
                  <joint name="right_ankle_roll_joint" pos="0 0 0" axis="1 0 0" range="-0.2618 0.2618" actuatorfrcrange="-50 50"/>
                  <geom type="mesh" contype="0" conaffinity="0" group="1" density="0" rgba="0.2 0.2 0.2 1" mesh="right_ankle_roll_link"/>
                  <geom size="0.005" pos="-0.05 0.025 -0.03" rgba="0.2 0.2 0.2 1"/>
                  <geom size="0.005" pos="-0.05 -0.025 -0.03" rgba="0.2 0.2 0.2 1"/>
                  <geom size="0.005" pos="0.12 0.03 -0.03" rgba="0.2 0.2 0.2 1"/>
                  <geom size="0.005" pos="0.12 -0.03 -0.03" rgba="0.2 0.2 0.2 1"/>
                </body>
              </body>
            </body>
          </body>
        </body>
      </body>
      <body name="waist_yaw_link">
        <inertial pos="0.003494 0.000233 0.018034" quat="0.289697 0.591001 -0.337795 0.672821" mass="0.214" diaginertia="0.000163531 0.000107714 0.000102205"/>
        <joint name="waist_yaw_joint" pos="0 0 0" axis="0 0 1" range="-2.618 2.618" actuatorfrcrange="-88 88"/>
        <geom type="mesh" contype="0" conaffinity="0" group="1" density="0" rgba="0.7 0.7 0.7 1" mesh="waist_yaw_link"/>
        <body name="waist_roll_link" pos="-0.0039635 0 0.044">
          <inertial pos="0 2.3e-05 0" quat="0.5 0.5 -0.5 0.5" mass="0.086" diaginertia="8.245e-06 7.079e-06 6.339e-06"/>
          <joint name="waist_roll_joint" pos="0 0 0" axis="1 0 0" range="-0.52 0.52" actuatorfrcrange="-50 50"/>
          <geom type="mesh" contype="0" conaffinity="0" group="1" density="0" rgba="0.7 0.7 0.7 1" mesh="waist_roll_link"/>
          <body name="torso_link">
            <inertial pos="0.00203158 0.000339683 0.184568" quat="0.999803 -6.03319e-05 0.0198256 0.00131986" mass="7.818" diaginertia="0.121847 0.109825 0.0273735"/>
            <joint name="waist_pitch_joint" pos="0 0 0" axis="0 1 0" range="-0.52 0.52" actuatorfrcrange="-50 50"/>
            <geom type="mesh" contype="0" conaffinity="0" group="1" density="0" rgba="0.7 0.7 0.7 1" mesh="torso_link"/>
            <geom type="mesh" rgba="0.7 0.7 0.7 1" mesh="torso_link"/>
            <geom pos="0.0039635 0 -0.044" quat="1 0 0 0" type="mesh" contype="0" conaffinity="0" group="1" density="0" rgba="0.2 0.2 0.2 1" mesh="logo_link"/>
            <geom pos="0.0039635 0 -0.044" quat="1 0 0 0" type="mesh" rgba="0.2 0.2 0.2 1" mesh="logo_link"/>
            <geom pos="0.0039635 0 -0.044" type="mesh" contype="0" conaffinity="0" group="1" density="0" rgba="0.2 0.2 0.2 1" mesh="head_link"/>
            <geom pos="0.0039635 0 -0.044" type="mesh" rgba="0.2 0.2 0.2 1" mesh="head_link"/>
            <site name="imu_in_torso" size="0.01" pos="-0.03959 -0.00224 0.14792"/>
            <body name="left_shoulder_pitch_link" pos="0.0039563 0.10022 0.24778" quat="0.990264 0.139201 1.38722e-05 -9.86868e-05">
              <inertial pos="0 0.035892 -0.011628" quat="0.654152 0.0130458 -0.326267 0.68225" mass="0.718" diaginertia="0.000465864 0.000432842 0.000406394"/>
              <joint name="left_shoulder_pitch_joint" pos="0 0 0" axis="0 1 0" range="-3.0892 2.6704" actuatorfrcrange="-25 25"/>
              <geom type="mesh" contype="0" conaffinity="0" group="1" density="0" rgba="0.7 0.7 0.7 1" mesh="left_shoulder_pitch_link"/>
              <geom size="0.03 0.025" pos="0 0.04 -0.01" quat="0.707107 0 0.707107 0" type="cylinder" rgba="0.7 0.7 0.7 1"/>
              <body name="left_shoulder_roll_link" pos="0 0.038 -0.013831" quat="0.990268 -0.139172 0 0">
                <inertial pos="-0.000227 0.00727 -0.063243" quat="0.701256 -0.0196223 -0.00710317 0.712604" mass="0.643" diaginertia="0.000691311 0.000618011 0.000388977"/>
                <joint name="left_shoulder_roll_joint" pos="0 0 0" axis="1 0 0" range="-1.5882 2.2515" actuatorfrcrange="-25 25"/>
                <geom type="mesh" contype="0" conaffinity="0" group="1" density="0" rgba="0.7 0.7 0.7 1" mesh="left_shoulder_roll_link"/>
                <geom size="0.03 0.015" pos="-0.004 0.006 -0.053" type="cylinder" rgba="0.7 0.7 0.7 1"/>
                <body name="left_shoulder_yaw_link" pos="0 0.00624 -0.1032">
                  <inertial pos="0.010773 -0.002949 -0.072009" quat="0.716879 -0.0964829 -0.0679942 0.687134" mass="0.734" diaginertia="0.00106187 0.00103217 0.000400661"/>
                  <joint name="left_shoulder_yaw_joint" pos="0 0 0" axis="0 0 1" range="-2.618 2.618" actuatorfrcrange="-25 25"/>
                  <geom type="mesh" contype="0" conaffinity="0" group="1" density="0" rgba="0.7 0.7 0.7 1" mesh="left_shoulder_yaw_link"/>
                  <geom type="mesh" rgba="0.7 0.7 0.7 1" mesh="left_shoulder_yaw_link"/>
                  <body name="left_elbow_link" pos="0.015783 0 -0.080518">
                    <inertial pos="0.064956 0.004454 -0.010062" quat="0.541765 0.636132 0.388821 0.388129" mass="0.6" diaginertia="0.000443035 0.000421612 0.000259353"/>
                    <joint name="left_elbow_joint" pos="0 0 0" axis="0 1 0" range="-1.0472 2.0944" actuatorfrcrange="-25 25"/>
                    <geom type="mesh" contype="0" conaffinity="0" group="1" density="0" rgba="0.7 0.7 0.7 1" mesh="left_elbow_link"/>
                    <geom type="mesh" rgba="0.7 0.7 0.7 1" mesh="left_elbow_link"/>
                    <body name="left_wrist_roll_link" pos="0.1 0.00188791 -0.01">
                      <inertial pos="0.0171394 0.000537591 4.8864e-07" quat="0.575338 0.411667 -0.574906 0.411094" mass="0.085445" diaginertia="5.48211e-05 4.96646e-05 3.57798e-05"/>
                      <joint name="left_wrist_roll_joint" pos="0 0 0" axis="1 0 0" range="-1.97222 1.97222" actuatorfrcrange="-25 25"/>
                      <geom type="mesh" contype="0" conaffinity="0" group="1" density="0" rgba="0.7 0.7 0.7 1" mesh="left_wrist_roll_link"/>
                      <geom type="mesh" rgba="0.7 0.7 0.7 1" mesh="left_wrist_roll_link"/>
                      <body name="left_wrist_pitch_link" pos="0.038 0 0">
                        <inertial pos="0.0229999 -0.00111685 -0.00111658" quat="0.249998 0.661363 0.293036 0.643608" mass="0.48405" diaginertia="0.000430353 0.000429873 0.000164648"/>
                        <joint name="left_wrist_pitch_joint" pos="0 0 0" axis="0 1 0" range="-1.61443 1.61443" actuatorfrcrange="-5 5"/>
                        <geom type="mesh" contype="0" conaffinity="0" group="1" density="0" rgba="0.7 0.7 0.7 1" mesh="left_wrist_pitch_link"/>
                        <geom type="mesh" rgba="0.7 0.7 0.7 1" mesh="left_wrist_pitch_link"/>
                        <body name="left_wrist_yaw_link" pos="0.046 0 0">
                          <inertial pos="0.0885506 0.00212216 -0.000374562" quat="0.487149 0.493844 0.513241 0.505358" mass="0.457415" diaginertia="0.00105989 0.000895419 0.000323842"/>
                          <joint name="left_wrist_yaw_joint" pos="0 0 0" axis="0 0 1" range="-1.61443 1.61443" actuatorfrcrange="-5 5"/>
                          <geom type="mesh" contype="0" conaffinity="0" group="1" density="0" rgba="0.7 0.7 0.7 1" mesh="left_wrist_yaw_link"/>
                          <geom type="mesh" rgba="0.7 0.7 0.7 1" mesh="left_wrist_yaw_link"/>
                          <!-- ===== Inspire Hand L ===== -->
                          <body name="L_hand_base_link" pos="0.04 0.003 0" quat="0.707107 0.000000 0.000000 0.707107">
                            <inertial pos="-0.002551 -0.066047 -0.0019357" mass="0.14143" diaginertia="0.0001234 8.3835e-05 7.7231e-05"/>
                            <geom type="mesh" contype="0" conaffinity="0" group="1" density="0" rgba="0.9 0.85 0.75 1" mesh="L_hand_base_link"/>
                            <geom type="mesh" rgba="0.9 0.85 0.75 1" mesh="L_hand_base_link"/>

                            <!-- THUMB -->
                            <body name="L_thumb_proximal_base" pos="-0.01696 -0.0691 0.02045" euler="1.5708 -1.5708 0">
                              <inertial pos="0.0048817 0.00038782 -0.00722" mass="0.0018869" diaginertia="5.5158e-08 8.2164e-08 6.7434e-08"/>
                              <joint name="L_thumb_proximal_yaw_joint" type="hinge" axis="0 0 1" range="-0.1 1.3" actuatorfrcrange="-1 1"/>
                              <geom type="mesh" contype="0" conaffinity="0" group="1" density="0" rgba="0.9 0.85 0.75 1" mesh="inspire_L_Link11"/>
                              <geom type="mesh" rgba="0.9 0.85 0.75 1" mesh="inspire_L_Link11"/>
                              <body name="L_thumb_proximal" pos="0.0099867 0.0098242 -0.0089" euler="-1.5708 0 0.16939">
                                <inertial pos="0.021936 -0.01279 -0.0080386" mass="0.0066101" diaginertia="1.5693e-06 1.7356e-06 2.787e-06"/>
                                <joint name="L_thumb_proximal_pitch_joint" type="hinge" axis="0 0 -1" range="0 0.5" actuatorfrcrange="-1 1"/>
                                <geom type="mesh" contype="0" conaffinity="0" group="1" density="0" rgba="0.9 0.85 0.75 1" mesh="inspire_L_Link12"/>
                                <geom type="mesh" rgba="0.9 0.85 0.75 1" mesh="inspire_L_Link12"/>
                                <body name="L_thumb_intermediate" pos="0.04407 -0.034553 -0.0008">
                                  <inertial pos="0.0095531 0.0016282 -0.0072002" mass="0.0037844" diaginertia="3.6981e-07 3.2395e-07 4.6532e-07"/>
                                  <joint name="L_thumb_intermediate_joint" type="hinge" axis="0 0 -1" range="0 0.8" actuatorfrcrange="-1 1"/>
                                  <geom type="mesh" contype="0" conaffinity="0" group="1" density="0" rgba="0.9 0.85 0.75 1" mesh="inspire_L_Link13"/>
                                  <geom type="mesh" rgba="0.9 0.85 0.75 1" mesh="inspire_L_Link13"/>
                                  <body name="L_thumb_distal" pos="0.020248 -0.010156 -0.0012">
                                    <inertial pos="0.0092888 -0.004953 -0.0060033" mass="0.003344" diaginertia="1.3632e-07 1.4052e-07 2.0026e-07"/>
                                    <joint name="L_thumb_distal_joint" type="hinge" axis="0 0 -1" range="0 1.2" actuatorfrcrange="-1 1"/>
                                    <geom type="mesh" contype="0" conaffinity="0" group="1" density="0" rgba="0.9 0.85 0.75 1" mesh="inspire_L_Link14"/>
                                    <geom type="mesh" rgba="0.9 0.85 0.75 1" mesh="inspire_L_Link14"/>
                                    <site name="L_thumb_tip" pos="0.015 -0.013 -0.004" size="0.005"/>
                                  </body>
                                </body>
                              </body>
                            </body>

                            <!-- INDEX -->
                            <body name="L_index_proximal" pos="0.00028533 -0.13653 0.032268" euler="-0.034907 0 0">
                              <inertial pos="0.0012971 -0.011934 -0.0059998" mass="0.0042405" diaginertia="6.6215e-07 2.1167e-07 6.9402e-07"/>
                              <joint name="L_index_proximal_joint" type="hinge" axis="0 0 -1" range="0 1.7" actuatorfrcrange="-1 1"/>
                              <geom type="mesh" contype="0" conaffinity="0" group="1" density="0" rgba="0.9 0.85 0.75 1" mesh="inspire_L_Link15"/>
                              <geom type="mesh" rgba="0.9 0.85 0.75 1" mesh="inspire_L_Link15"/>
                              <body name="L_index_intermediate" pos="-0.0024229 -0.032041 -0.001">
                                <inertial pos="0.0021753 -0.019567 -0.005" mass="0.0045682" diaginertia="7.6284e-07 9.4308e-08 7.8176e-07"/>
                                <joint name="L_index_intermediate_joint" type="hinge" axis="0 0 -1" range="0 1.7" actuatorfrcrange="-1 1"/>
                                <geom type="mesh" contype="0" conaffinity="0" group="1" density="0" rgba="0.9 0.85 0.75 1" mesh="inspire_L_Link16"/>
                                <geom type="mesh" rgba="0.9 0.85 0.75 1" mesh="inspire_L_Link16"/>
                                <site name="L_index_tip" pos="-0.005 -0.04 -0.004" size="0.005"/>
                              </body>
                            </body>

                            <!-- MIDDLE -->
                            <body name="L_middle_proximal" pos="0.00028533 -0.1371 0.01295" euler="0 0 0">
                              <inertial pos="0.0012971 -0.011934 -0.0059999" mass="0.0042405" diaginertia="6.6215e-07 2.1167e-07 6.9402e-07"/>
                              <joint name="L_middle_proximal_joint" type="hinge" axis="0 0 -1" range="0 1.7" actuatorfrcrange="-1 1"/>
                              <geom type="mesh" contype="0" conaffinity="0" group="1" density="0" rgba="0.9 0.85 0.75 1" mesh="inspire_L_Link17"/>
                              <geom type="mesh" rgba="0.9 0.85 0.75 1" mesh="inspire_L_Link17"/>
                              <body name="L_middle_intermediate" pos="-0.0024229 -0.032041 -0.001">
                                <inertial pos="0.001921 -0.020796 -0.0049999" mass="0.0050397" diaginertia="9.5823e-07 1.0646e-07 9.8385e-07"/>
                                <joint name="L_middle_intermediate_joint" type="hinge" axis="0 0 -1" range="0 1.7" actuatorfrcrange="-1 1"/>
                                <geom type="mesh" contype="0" conaffinity="0" group="1" density="0" rgba="0.9 0.85 0.75 1" mesh="inspire_L_Link18"/>
                                <geom type="mesh" rgba="0.9 0.85 0.75 1" mesh="inspire_L_Link18"/>
                                <site name="L_middle_tip" pos="-0.005 -0.045 -0.004" size="0.005"/>
                              </body>
                            </body>

                            <!-- RING -->
                            <body name="L_ring_proximal" pos="0.00028533 -0.13691 -0.0062872" euler="0.05236 0 0">
                              <inertial pos="0.0012971 -0.011934 -0.0059999" mass="0.0042405" diaginertia="6.6215e-07 2.1167e-07 6.9402e-07"/>
                              <joint name="L_ring_proximal_joint" type="hinge" axis="0 0 -1" range="0 1.7" actuatorfrcrange="-1 1"/>
                              <geom type="mesh" contype="0" conaffinity="0" group="1" density="0" rgba="0.9 0.85 0.75 1" mesh="inspire_L_Link19"/>
                              <geom type="mesh" rgba="0.9 0.85 0.75 1" mesh="inspire_L_Link19"/>
                              <body name="L_ring_intermediate" pos="-0.0024229 -0.032041 -0.001">
                                <inertial pos="0.0021753 -0.019567 -0.005" mass="0.0045682" diaginertia="7.6285e-07 9.4308e-08 7.8176e-07"/>
                                <joint name="L_ring_intermediate_joint" type="hinge" axis="0 0 -1" range="0 1.7" actuatorfrcrange="-1 1"/>
                                <geom type="mesh" contype="0" conaffinity="0" group="1" density="0" rgba="0.9 0.85 0.75 1" mesh="inspire_L_Link20"/>
                                <geom type="mesh" rgba="0.9 0.85 0.75 1" mesh="inspire_L_Link20"/>
                                <site name="L_ring_tip" pos="-0.002 -0.04 -0.004" size="0.005"/>
                              </body>
                            </body>

                            <!-- PINKY -->
                            <body name="L_pinky_proximal" pos="0.00028533 -0.13571 -0.025488" euler="0.10472 0 0">
                              <inertial pos="0.0012971 -0.011934 -0.0059999" mass="0.0042405" diaginertia="6.6215e-07 2.1167e-07 6.9402e-07"/>
                              <joint name="L_pinky_proximal_joint" type="hinge" axis="0 0 -1" range="0 1.7" actuatorfrcrange="-1 1"/>
                              <geom type="mesh" contype="0" conaffinity="0" group="1" density="0" rgba="0.9 0.85 0.75 1" mesh="inspire_L_Link21"/>
                              <geom type="mesh" rgba="0.9 0.85 0.75 1" mesh="inspire_L_Link21"/>
                              <body name="L_pinky_intermediate" pos="-0.0024229 -0.032041 -0.001">
                                <inertial pos="0.0024788 -0.016208 -0.0050001" mass="0.0036036" diaginertia="4.3923e-07 7.0315e-08 4.4881e-07"/>
                                <joint name="L_pinky_intermediate_joint" type="hinge" axis="0 0 -1" range="0 1.7" actuatorfrcrange="-1 1"/>
                                <geom type="mesh" contype="0" conaffinity="0" group="1" density="0" rgba="0.9 0.85 0.75 1" mesh="inspire_L_Link22"/>
                                <geom type="mesh" rgba="0.9 0.85 0.75 1" mesh="inspire_L_Link22"/>
                                <site name="L_pinky_tip" pos="-0.002 -0.032 -0.004" size="0.005"/>
                              </body>
                            </body>

                          </body>
                          <!-- ===== End Inspire Hand L ===== -->

                        </body>
                      </body>
                    </body>
                  </body>
                </body>
              </body>
            </body>
            <body name="right_shoulder_pitch_link" pos="0.0039563 -0.10021 0.24778" quat="0.990264 -0.139201 1.38722e-05 9.86868e-05">
              <inertial pos="0 -0.035892 -0.011628" quat="0.68225 -0.326267 0.0130458 0.654152" mass="0.718" diaginertia="0.000465864 0.000432842 0.000406394"/>
              <joint name="right_shoulder_pitch_joint" pos="0 0 0" axis="0 1 0" range="-3.0892 2.6704" actuatorfrcrange="-25 25"/>
              <geom type="mesh" contype="0" conaffinity="0" group="1" density="0" rgba="0.7 0.7 0.7 1" mesh="right_shoulder_pitch_link"/>
              <geom size="0.03 0.025" pos="0 -0.04 -0.01" quat="0.707107 0 0.707107 0" type="cylinder" rgba="0.7 0.7 0.7 1"/>
              <body name="right_shoulder_roll_link" pos="0 -0.038 -0.013831" quat="0.990268 0.139172 0 0">
                <inertial pos="-0.000227 -0.00727 -0.063243" quat="0.712604 -0.00710317 -0.0196223 0.701256" mass="0.643" diaginertia="0.000691311 0.000618011 0.000388977"/>
                <joint name="right_shoulder_roll_joint" pos="0 0 0" axis="1 0 0" range="-2.2515 1.5882" actuatorfrcrange="-25 25"/>
                <geom type="mesh" contype="0" conaffinity="0" group="1" density="0" rgba="0.7 0.7 0.7 1" mesh="right_shoulder_roll_link"/>
                <geom size="0.03 0.015" pos="-0.004 -0.006 -0.053" type="cylinder" rgba="0.7 0.7 0.7 1"/>
                <body name="right_shoulder_yaw_link" pos="0 -0.00624 -0.1032">
                  <inertial pos="0.010773 0.002949 -0.072009" quat="0.687134 -0.0679942 -0.0964829 0.716879" mass="0.734" diaginertia="0.00106187 0.00103217 0.000400661"/>
                  <joint name="right_shoulder_yaw_joint" pos="0 0 0" axis="0 0 1" range="-2.618 2.618" actuatorfrcrange="-25 25"/>
                  <geom type="mesh" contype="0" conaffinity="0" group="1" density="0" rgba="0.7 0.7 0.7 1" mesh="right_shoulder_yaw_link"/>
                  <geom type="mesh" rgba="0.7 0.7 0.7 1" mesh="right_shoulder_yaw_link"/>
                  <body name="right_elbow_link" pos="0.015783 0 -0.080518">
                    <inertial pos="0.064956 -0.004454 -0.010062" quat="0.388129 0.388821 0.636132 0.541765" mass="0.6" diaginertia="0.000443035 0.000421612 0.000259353"/>
                    <joint name="right_elbow_joint" pos="0 0 0" axis="0 1 0" range="-1.0472 2.0944" actuatorfrcrange="-25 25"/>
                    <geom type="mesh" contype="0" conaffinity="0" group="1" density="0" rgba="0.7 0.7 0.7 1" mesh="right_elbow_link"/>
                    <geom type="mesh" rgba="0.7 0.7 0.7 1" mesh="right_elbow_link"/>
                    <body name="right_wrist_roll_link" pos="0.1 -0.00188791 -0.01">
                      <inertial pos="0.0171394 -0.000537591 4.8864e-07" quat="0.411667 0.575338 -0.411094 0.574906" mass="0.085445" diaginertia="5.48211e-05 4.96646e-05 3.57798e-05"/>
                      <joint name="right_wrist_roll_joint" pos="0 0 0" axis="1 0 0" range="-1.97222 1.97222" actuatorfrcrange="-25 25"/>
                      <geom type="mesh" contype="0" conaffinity="0" group="1" density="0" rgba="0.7 0.7 0.7 1" mesh="right_wrist_roll_link"/>
                      <geom type="mesh" rgba="0.7 0.7 0.7 1" mesh="right_wrist_roll_link"/>
                      <body name="right_wrist_pitch_link" pos="0.038 0 0">
                        <inertial pos="0.0229999 0.00111685 -0.00111658" quat="0.643608 0.293036 0.661363 0.249998" mass="0.48405" diaginertia="0.000430353 0.000429873 0.000164648"/>
                        <joint name="right_wrist_pitch_joint" pos="0 0 0" axis="0 1 0" range="-1.61443 1.61443" actuatorfrcrange="-5 5"/>
                        <geom type="mesh" contype="0" conaffinity="0" group="1" density="0" rgba="0.7 0.7 0.7 1" mesh="right_wrist_pitch_link"/>
                        <geom type="mesh" rgba="0.7 0.7 0.7 1" mesh="right_wrist_pitch_link"/>
                        <body name="right_wrist_yaw_link" pos="0.046 0 0">
                          <inertial pos="0.0885506 -0.00212216 -0.000374562" quat="0.505358 0.513241 0.493844 0.487149" mass="0.457415" diaginertia="0.00105989 0.000895419 0.000323842"/>
                          <joint name="right_wrist_yaw_joint" pos="0 0 0" axis="0 0 1" range="-1.61443 1.61443" actuatorfrcrange="-5 5"/>
                          <geom type="mesh" contype="0" conaffinity="0" group="1" density="0" rgba="0.7 0.7 0.7 1" mesh="right_wrist_yaw_link"/>
                          <geom type="mesh" rgba="0.7 0.7 0.7 1" mesh="right_wrist_yaw_link"/>

                          <!-- ===== Inspire Hand R ===== -->
                          <body name="R_hand_base_link" pos="0.04 -0.003 0" euler="3.1416 0 1.5708">
                            <inertial pos="-0.0025264 -0.066047 0.0019598" mass="0.14143" diaginertia="0.00012281 8.3832e-05 7.6663e-05"/>
                            <geom type="mesh" contype="0" conaffinity="0" group="1" density="0" rgba="0.9 0.85 0.75 1" mesh="R_hand_base_link"/>
                            <geom type="mesh" rgba="0.9 0.85 0.75 1" mesh="R_hand_base_link"/>

                            <!-- THUMB -->
                            <body name="R_thumb_proximal_base" pos="-0.01696 -0.0691 -0.02045" euler="-1.5708 1.5708 -3.1416">
                              <inertial pos="-0.0048064 0.0009382 -0.00757" mass="0.0018869" diaginertia="5.816e-08 7.9161e-08 6.7433e-08"/>
                              <joint name="R_thumb_proximal_yaw_joint" type="hinge" axis="0 0 1" range="-0.1 1.3" actuatorfrcrange="-1 1"/>
                              <geom type="mesh" contype="0" conaffinity="0" group="1" density="0" rgba="0.9 0.85 0.75 1" mesh="inspire_R_Link11"/>
                              <geom type="mesh" rgba="0.9 0.85 0.75 1" mesh="inspire_R_Link11"/>
                              <body name="R_thumb_proximal" pos="-0.0088099 -0.010892 -0.00925" euler="1.5708 0 2.8587">
                                <inertial pos="0.021932 0.012785 -0.0080386" mass="0.0066075" diaginertia="1.5686e-06 1.7353e-06 2.786e-06"/>
                                <joint name="R_thumb_proximal_pitch_joint" type="hinge" axis="0 0 1" range="0 0.5" actuatorfrcrange="-1 1"/>
                                <geom type="mesh" contype="0" conaffinity="0" group="1" density="0" rgba="0.9 0.85 0.75 1" mesh="inspire_R_Link12"/>
                                <geom type="mesh" rgba="0.9 0.85 0.75 1" mesh="inspire_R_Link12"/>
                                <body name="R_thumb_intermediate" pos="0.04407 0.034553 -0.0008">
                                  <inertial pos="0.0095544 -0.0016282 -0.0071997" mass="0.0037847" diaginertia="3.6981e-07 3.2394e-07 4.6531e-07"/>
                                  <joint name="R_thumb_intermediate_joint" type="hinge" axis="0 0 1" range="0 0.8" actuatorfrcrange="-1 1"/>
                                  <geom type="mesh" contype="0" conaffinity="0" group="1" density="0" rgba="0.9 0.85 0.75 1" mesh="inspire_R_Link13"/>
                                  <geom type="mesh" rgba="0.9 0.85 0.75 1" mesh="inspire_R_Link13"/>
                                  <body name="R_thumb_distal" pos="0.020248 0.010156 -0.0012">
                                    <inertial pos="0.0092888 0.0049529 -0.0060033" mass="0.0033441" diaginertia="1.3632e-07 1.4052e-07 2.0026e-07"/>
                                    <joint name="R_thumb_distal_joint" type="hinge" axis="0 0 1" range="0 1.2" actuatorfrcrange="-1 1"/>
                                    <geom type="mesh" contype="0" conaffinity="0" group="1" density="0" rgba="0.9 0.85 0.75 1" mesh="inspire_R_Link14"/>
                                    <geom type="mesh" rgba="0.9 0.85 0.75 1" mesh="inspire_R_Link14"/>
                                    <site name="R_thumb_tip" pos="0.015 0.013 -0.004" size="0.005"/>
                                  </body>
                                </body>
                              </body>
                            </body>

                            <!-- INDEX -->
                            <body name="R_index_proximal" pos="0.00028533 -0.13653 -0.032268" euler="-3.1067 0 0">
                              <inertial pos="0.0012259 0.011942 -0.0060001" mass="0.0042403" diaginertia="6.6232e-07 2.1146e-07 6.9398e-07"/>
                              <joint name="R_index_proximal_joint" type="hinge" axis="0 0 1" range="0 1.7" actuatorfrcrange="-1 1"/>
                              <geom type="mesh" contype="0" conaffinity="0" group="1" density="0" rgba="0.9 0.85 0.75 1" mesh="inspire_R_Link15"/>
                              <geom type="mesh" rgba="0.9 0.85 0.75 1" mesh="inspire_R_Link15"/>
                              <body name="R_index_intermediate" pos="-0.002 0.032 -0.001">
                                <inertial pos="0.0019697 0.019589 -0.005" mass="0.0045683" diaginertia="7.6286e-07 9.431e-08 7.8177e-07"/>
                                <joint name="R_index_intermediate_joint" type="hinge" axis="0 0 1" range="0 1.7" actuatorfrcrange="-1 1"/>
                                <geom type="mesh" contype="0" conaffinity="0" group="1" density="0" rgba="0.9 0.85 0.75 1" mesh="inspire_R_Link16"/>
                                <geom type="mesh" rgba="0.9 0.85 0.75 1" mesh="inspire_R_Link16"/>
                                <site name="R_index_tip" pos="-0.005 0.04 -0.004" size="0.005"/>
                              </body>
                            </body>

                            <!-- MIDDLE -->
                            <body name="R_middle_proximal" pos="0.00028533 -0.1371 -0.01295" euler="-3.1416 0 0">
                              <inertial pos="0.001297 0.011934 -0.0060001" mass="0.0042403" diaginertia="6.6211e-07 2.1167e-07 6.9397e-07"/>
                              <joint name="R_middle_proximal_joint" type="hinge" axis="0 0 1" range="0 1.7" actuatorfrcrange="-1 1"/>
                              <geom type="mesh" contype="0" conaffinity="0" group="1" density="0" rgba="0.9 0.85 0.75 1" mesh="inspire_R_Link17"/>
                              <geom type="mesh" rgba="0.9 0.85 0.75 1" mesh="inspire_R_Link17"/>
                              <body name="R_middle_intermediate" pos="-0.0024229 0.032041 -0.001">
                                <inertial pos="0.001921 0.020796 -0.005" mass="0.0050396" diaginertia="9.5822e-07 1.0646e-07 9.8384e-07"/>
                                <joint name="R_middle_intermediate_joint" type="hinge" axis="0 0 1" range="0 1.7" actuatorfrcrange="-1 1"/>
                                <geom type="mesh" contype="0" conaffinity="0" group="1" density="0" rgba="0.9 0.85 0.75 1" mesh="inspire_R_Link18"/>
                                <geom type="mesh" rgba="0.9 0.85 0.75 1" mesh="inspire_R_Link18"/>
                                <site name="R_middle_tip" pos="-0.005 0.045 -0.004" size="0.005"/>
                              </body>
                            </body>

                            <!-- RING -->
                            <body name="R_ring_proximal" pos="0.00028533 -0.13691 0.0062872" euler="3.0892 0 0">
                              <inertial pos="0.001297 0.011934 -0.0060002" mass="0.0042403" diaginertia="6.6211e-07 2.1167e-07 6.9397e-07"/>
                              <joint name="R_ring_proximal_joint" type="hinge" axis="0 0 1" range="0 1.7" actuatorfrcrange="-1 1"/>
                              <geom type="mesh" contype="0" conaffinity="0" group="1" density="0" rgba="0.9 0.85 0.75 1" mesh="inspire_R_Link19"/>
                              <geom type="mesh" rgba="0.9 0.85 0.75 1" mesh="inspire_R_Link19"/>
                              <body name="R_ring_intermediate" pos="-0.0024229 0.032041 -0.001">
                                <inertial pos="0.0021753 0.019567 -0.005" mass="0.0045683" diaginertia="7.6286e-07 9.431e-08 7.8177e-07"/>
                                <joint name="R_ring_intermediate_joint" type="hinge" axis="0 0 1" range="0 1.7" actuatorfrcrange="-1 1"/>
                                <geom type="mesh" contype="0" conaffinity="0" group="1" density="0" rgba="0.9 0.85 0.75 1" mesh="inspire_R_Link20"/>
                                <geom type="mesh" rgba="0.9 0.85 0.75 1" mesh="inspire_R_Link20"/>
                                <site name="R_ring_tip" pos="-0.002 0.04 -0.004" size="0.005"/>
                              </body>
                            </body>

                            <!-- PINKY -->
                            <body name="R_pinky_proximal" pos="0.00028533 -0.13571 0.025488" euler="3.0369 0 0">
                              <inertial pos="0.001297 0.011934 -0.0060001" mass="0.0042403" diaginertia="6.6211e-07 2.1167e-07 6.9397e-07"/>
                              <joint name="R_pinky_proximal_joint" type="hinge" axis="0 0 1" range="0 1.7" actuatorfrcrange="-1 1"/>
                              <geom type="mesh" contype="0" conaffinity="0" group="1" density="0" rgba="0.9 0.85 0.75 1" mesh="inspire_R_Link21"/>
                              <geom type="mesh" rgba="0.9 0.85 0.75 1" mesh="inspire_R_Link21"/>
                              <body name="R_pinky_intermediate" pos="-0.0024229 0.032041 -0.001">
                                <inertial pos="0.0024748 0.016203 -0.0050031" mass="0.0035996" diaginertia="4.3913e-07 7.0247e-08 4.4867e-07"/>
                                <joint name="R_pinky_intermediate_joint" type="hinge" axis="0 0 1" range="0 1.7" actuatorfrcrange="-1 1"/>
                                <geom type="mesh" contype="0" conaffinity="0" group="1" density="0" rgba="0.9 0.85 0.75 1" mesh="inspire_R_Link22"/>
                                <geom type="mesh" rgba="0.9 0.85 0.75 1" mesh="inspire_R_Link22"/>
                                <site name="R_pinky_tip" pos="-0.002 0.032 -0.004" size="0.005"/>
                              </body>
                            </body>

                          </body>
                          <!-- ===== End Inspire Hand R ===== -->

                        </body>
                      </body>
                    </body>
                  </body>
                </body>
              </body>
            </body>
          </body>
        </body>
      </body>
    </body>
  </worldbody>




  <!-- Mimic joints Inspire Hand: distales siguen a proximales -->
  <equality>
    <!-- LEFT thumb -->
    <joint name="L_thumb_int_mimic"  joint1="L_thumb_intermediate_joint" joint2="L_thumb_proximal_pitch_joint" polycoef="0 1.6 0 0 0"/>
    <joint name="L_thumb_dis_mimic"  joint1="L_thumb_distal_joint"       joint2="L_thumb_proximal_pitch_joint" polycoef="0 2.4 0 0 0"/>
    <!-- LEFT fingers -->
    <joint name="L_index_int_mimic"  joint1="L_index_intermediate_joint"  joint2="L_index_proximal_joint"  polycoef="0 1 0 0 0"/>
    <joint name="L_middle_int_mimic" joint1="L_middle_intermediate_joint" joint2="L_middle_proximal_joint" polycoef="0 1 0 0 0"/>
    <joint name="L_ring_int_mimic"   joint1="L_ring_intermediate_joint"   joint2="L_ring_proximal_joint"   polycoef="0 1 0 0 0"/>
    <joint name="L_pinky_int_mimic"  joint1="L_pinky_intermediate_joint"  joint2="L_pinky_proximal_joint"  polycoef="0 1 0 0 0"/>
    <!-- RIGHT thumb -->
    <joint name="R_thumb_int_mimic"  joint1="R_thumb_intermediate_joint" joint2="R_thumb_proximal_pitch_joint" polycoef="0 1.6 0 0 0"/>
    <joint name="R_thumb_dis_mimic"  joint1="R_thumb_distal_joint"       joint2="R_thumb_proximal_pitch_joint" polycoef="0 2.4 0 0 0"/>
    <!-- RIGHT fingers -->
    <joint name="R_index_int_mimic"  joint1="R_index_intermediate_joint"  joint2="R_index_proximal_joint"  polycoef="0 1 0 0 0"/>
    <joint name="R_middle_int_mimic" joint1="R_middle_intermediate_joint" joint2="R_middle_proximal_joint" polycoef="0 1 0 0 0"/>
    <joint name="R_ring_int_mimic"   joint1="R_ring_intermediate_joint"   joint2="R_ring_proximal_joint"   polycoef="0 1 0 0 0"/>
    <joint name="R_pinky_int_mimic"  joint1="R_pinky_intermediate_joint"  joint2="R_pinky_proximal_joint"  polycoef="0 1 0 0 0"/>
  </equality>

  <sensor>
    <gyro name="imu-torso-angular-velocity" site="imu_in_torso" noise="5e-4" cutoff="34.9"/>
    <accelerometer name="imu-torso-linear-acceleration" site="imu_in_torso" noise="1e-2" cutoff="157"/>
    <gyro name="imu-pelvis-angular-velocity" site="imu_in_pelvis" noise="5e-4" cutoff="34.9"/>
    <accelerometer name="imu-pelvis-linear-acceleration" site="imu_in_pelvis" noise="1e-2" cutoff="157"/>
    <subtreeangmom name="root_angmom" body="pelvis"/>
  </sensor>


  <!-- setup scene -->
  <statistic center="1.0 0.7 1.0" extent="0.8"/>
  <visual>
    <headlight diffuse="0.6 0.6 0.6" ambient="0.1 0.1 0.1" specular="0.9 0.9 0.9"/>
    <rgba haze="0.15 0.25 0.35 1"/>
    <global azimuth="-140" elevation="-20"/>
  </visual>
  <asset>
    <texture type="skybox" builtin="flat" rgb1="0 0 0" rgb2="0 0 0" width="512" height="3072"/>
    <texture type="2d" name="groundplane" builtin="checker" mark="edge" rgb1="0.2 0.3 0.4" rgb2="0.1 0.2 0.3" markrgb="0.8 0.8 0.8" width="300" height="300"/>
    <material name="groundplane" texture="groundplane" texuniform="true" texrepeat="5 5" reflectance="0.2"/>
  </asset>
  <worldbody>
    <light pos="1 0 3.5" dir="0 0 -1" directional="true"/>
    <geom name="floor" size="0 0 0.05" type="plane" material="groundplane"/>
  </worldbody>
</mujoco>